[2024-12-02T06:40:31.359+0000] {taskinstance.py:1957} INFO - Dependencies all met for dep_context=non-requeueable deps ti=<TaskInstance: data_pipeline.run_pipeline manual__2024-12-02T06:40:28.738287+00:00 [queued]>
[2024-12-02T06:40:31.369+0000] {taskinstance.py:1957} INFO - Dependencies all met for dep_context=requeueable deps ti=<TaskInstance: data_pipeline.run_pipeline manual__2024-12-02T06:40:28.738287+00:00 [queued]>
[2024-12-02T06:40:31.369+0000] {taskinstance.py:2171} INFO - Starting attempt 1 of 1
[2024-12-02T06:40:31.784+0000] {taskinstance.py:2192} INFO - Executing <Task(PythonOperator): run_pipeline> on 2024-12-02 06:40:28.738287+00:00
[2024-12-02T06:40:31.793+0000] {standard_task_runner.py:60} INFO - Started process 391 to run task
[2024-12-02T06:40:31.796+0000] {standard_task_runner.py:87} INFO - Running: ['***', 'tasks', 'run', 'data_pipeline', 'run_pipeline', 'manual__2024-12-02T06:40:28.738287+00:00', '--job-id', '11', '--raw', '--subdir', 'DAGS_FOLDER/pipeline_data_quality.py', '--cfg-path', '/tmp/tmpicbdrauv']
[2024-12-02T06:40:31.799+0000] {standard_task_runner.py:88} INFO - Job 11: Subtask run_pipeline
[2024-12-02T06:40:31.844+0000] {task_command.py:423} INFO - Running <TaskInstance: data_pipeline.run_pipeline manual__2024-12-02T06:40:28.738287+00:00 [running]> on host 5a9264f98c35
[2024-12-02T06:40:31.919+0000] {taskinstance.py:2481} INFO - Exporting env vars: AIRFLOW_CTX_DAG_OWNER='***' AIRFLOW_CTX_DAG_ID='data_pipeline' AIRFLOW_CTX_TASK_ID='run_pipeline' AIRFLOW_CTX_EXECUTION_DATE='2024-12-02T06:40:28.738287+00:00' AIRFLOW_CTX_TRY_NUMBER='1' AIRFLOW_CTX_DAG_RUN_ID='manual__2024-12-02T06:40:28.738287+00:00'
[2024-12-02T06:40:31.925+0000] {taskinstance.py:2699} ERROR - Task failed with exception
Traceback (most recent call last):
  File "/home/airflow/.local/lib/python3.8/site-packages/airflow/models/taskinstance.py", line 433, in _execute_task
    result = execute_callable(context=context, **execute_callable_kwargs)
  File "/home/airflow/.local/lib/python3.8/site-packages/airflow/operators/python.py", line 199, in execute
    return_value = self.execute_callable()
  File "/home/airflow/.local/lib/python3.8/site-packages/airflow/operators/python.py", line 216, in execute_callable
    return self.python_callable(*self.op_args, **self.op_kwargs)
  File "/opt/airflow/dags/pipeline_data_quality.py", line 21, in pipeline
    df_cleaned = clean_data(input_path)
  File "/opt/airflow/src/data_cleaning.py", line 4, in clean_data
    df = pd.read_csv(file_path)
  File "/home/airflow/.local/lib/python3.8/site-packages/pandas/io/parsers/readers.py", line 912, in read_csv
    return _read(filepath_or_buffer, kwds)
  File "/home/airflow/.local/lib/python3.8/site-packages/pandas/io/parsers/readers.py", line 577, in _read
    parser = TextFileReader(filepath_or_buffer, **kwds)
  File "/home/airflow/.local/lib/python3.8/site-packages/pandas/io/parsers/readers.py", line 1407, in __init__
    self._engine = self._make_engine(f, self.engine)
  File "/home/airflow/.local/lib/python3.8/site-packages/pandas/io/parsers/readers.py", line 1661, in _make_engine
    self.handles = get_handle(
  File "/home/airflow/.local/lib/python3.8/site-packages/pandas/io/common.py", line 859, in get_handle
    handle = open(
FileNotFoundError: [Errno 2] No such file or directory: '/opt/airflow/data/input.csv'
[2024-12-02T06:40:31.941+0000] {taskinstance.py:1138} INFO - Marking task as FAILED. dag_id=data_pipeline, task_id=run_pipeline, execution_date=20241202T064028, start_date=20241202T064031, end_date=20241202T064031
[2024-12-02T06:40:31.958+0000] {standard_task_runner.py:107} ERROR - Failed to execute job 11 for task run_pipeline ([Errno 2] No such file or directory: '/opt/airflow/data/input.csv'; 391)
[2024-12-02T06:40:31.968+0000] {local_task_job_runner.py:234} INFO - Task exited with return code 1
[2024-12-02T06:40:31.985+0000] {taskinstance.py:3281} INFO - 0 downstream tasks scheduled from follow-on schedule check
