[2024-12-02T08:12:06.861+0000] {taskinstance.py:1957} INFO - Dependencies all met for dep_context=non-requeueable deps ti=<TaskInstance: main_data_pipeline.trigger_data_cleaning manual__2024-12-02T08:10:02.757666+00:00 [queued]>
[2024-12-02T08:12:06.870+0000] {taskinstance.py:1957} INFO - Dependencies all met for dep_context=requeueable deps ti=<TaskInstance: main_data_pipeline.trigger_data_cleaning manual__2024-12-02T08:10:02.757666+00:00 [queued]>
[2024-12-02T08:12:06.871+0000] {taskinstance.py:2171} INFO - Starting attempt 3 of 3
[2024-12-02T08:12:06.884+0000] {taskinstance.py:2192} INFO - Executing <Task(TriggerDagRunOperator): trigger_data_cleaning> on 2024-12-02 08:10:02.757666+00:00
[2024-12-02T08:12:06.892+0000] {standard_task_runner.py:60} INFO - Started process 104 to run task
[2024-12-02T08:12:06.894+0000] {standard_task_runner.py:87} INFO - Running: ['***', 'tasks', 'run', 'main_data_pipeline', 'trigger_data_cleaning', 'manual__2024-12-02T08:10:02.757666+00:00', '--job-id', '24', '--raw', '--subdir', 'DAGS_FOLDER/main_data_pipeline.py', '--cfg-path', '/tmp/tmp2lnjet0z']
[2024-12-02T08:12:06.895+0000] {standard_task_runner.py:88} INFO - Job 24: Subtask trigger_data_cleaning
[2024-12-02T08:12:06.942+0000] {task_command.py:423} INFO - Running <TaskInstance: main_data_pipeline.trigger_data_cleaning manual__2024-12-02T08:10:02.757666+00:00 [running]> on host b1ba4dce8a9e
[2024-12-02T08:12:07.015+0000] {taskinstance.py:2481} INFO - Exporting env vars: AIRFLOW_CTX_DAG_OWNER='***' AIRFLOW_CTX_DAG_ID='main_data_pipeline' AIRFLOW_CTX_TASK_ID='trigger_data_cleaning' AIRFLOW_CTX_EXECUTION_DATE='2024-12-02T08:10:02.757666+00:00' AIRFLOW_CTX_TRY_NUMBER='3' AIRFLOW_CTX_DAG_RUN_ID='manual__2024-12-02T08:10:02.757666+00:00'
[2024-12-02T08:12:07.037+0000] {taskinstance.py:2699} ERROR - Task failed with exception
Traceback (most recent call last):
  File "/home/airflow/.local/lib/python3.8/site-packages/airflow/models/taskinstance.py", line 428, in _execute_task
    result = execute_callable(context=context, **execute_callable_kwargs)
  File "/home/airflow/.local/lib/python3.8/site-packages/airflow/operators/trigger_dagrun.py", line 165, in execute
    dag_run = trigger_dag(
  File "/home/airflow/.local/lib/python3.8/site-packages/airflow/api/common/trigger_dag.py", line 122, in trigger_dag
    raise DagNotFound(f"Dag id {dag_id} not found in DagModel")
airflow.exceptions.DagNotFound: Dag id data_cleaning not found in DagModel
[2024-12-02T08:12:07.042+0000] {taskinstance.py:1138} INFO - Marking task as FAILED. dag_id=main_data_pipeline, task_id=trigger_data_cleaning, execution_date=20241202T081002, start_date=20241202T081206, end_date=20241202T081207
[2024-12-02T08:12:07.057+0000] {standard_task_runner.py:107} ERROR - Failed to execute job 24 for task trigger_data_cleaning (Dag id data_cleaning not found in DagModel; 104)
[2024-12-02T08:12:07.068+0000] {local_task_job_runner.py:234} INFO - Task exited with return code 1
[2024-12-02T08:12:07.100+0000] {taskinstance.py:3281} INFO - 0 downstream tasks scheduled from follow-on schedule check
