[2024-12-02T06:44:42.018+0000] {taskinstance.py:1957} INFO - Dependencies all met for dep_context=non-requeueable deps ti=<TaskInstance: data_pipeline.run_pipeline manual__2024-12-02T06:44:39.776028+00:00 [queued]>
[2024-12-02T06:44:42.026+0000] {taskinstance.py:1957} INFO - Dependencies all met for dep_context=requeueable deps ti=<TaskInstance: data_pipeline.run_pipeline manual__2024-12-02T06:44:39.776028+00:00 [queued]>
[2024-12-02T06:44:42.027+0000] {taskinstance.py:2171} INFO - Starting attempt 1 of 1
[2024-12-02T06:44:42.275+0000] {taskinstance.py:2192} INFO - Executing <Task(PythonOperator): run_pipeline> on 2024-12-02 06:44:39.776028+00:00
[2024-12-02T06:44:42.286+0000] {standard_task_runner.py:60} INFO - Started process 77 to run task
[2024-12-02T06:44:42.289+0000] {standard_task_runner.py:87} INFO - Running: ['***', 'tasks', 'run', 'data_pipeline', 'run_pipeline', 'manual__2024-12-02T06:44:39.776028+00:00', '--job-id', '14', '--raw', '--subdir', 'DAGS_FOLDER/pipeline_data_quality.py', '--cfg-path', '/tmp/tmphl7xjsyp']
[2024-12-02T06:44:42.298+0000] {standard_task_runner.py:88} INFO - Job 14: Subtask run_pipeline
[2024-12-02T06:44:42.397+0000] {task_command.py:423} INFO - Running <TaskInstance: data_pipeline.run_pipeline manual__2024-12-02T06:44:39.776028+00:00 [running]> on host 2dfbc067a1a0
[2024-12-02T06:44:42.495+0000] {taskinstance.py:2481} INFO - Exporting env vars: AIRFLOW_CTX_DAG_OWNER='***' AIRFLOW_CTX_DAG_ID='data_pipeline' AIRFLOW_CTX_TASK_ID='run_pipeline' AIRFLOW_CTX_EXECUTION_DATE='2024-12-02T06:44:39.776028+00:00' AIRFLOW_CTX_TRY_NUMBER='1' AIRFLOW_CTX_DAG_RUN_ID='manual__2024-12-02T06:44:39.776028+00:00'
[2024-12-02T06:46:14.884+0000] {taskinstance.py:2699} ERROR - Task failed with exception
Traceback (most recent call last):
  File "/home/airflow/.local/lib/python3.8/site-packages/airflow/models/taskinstance.py", line 433, in _execute_task
    result = execute_callable(context=context, **execute_callable_kwargs)
  File "/home/airflow/.local/lib/python3.8/site-packages/airflow/operators/python.py", line 199, in execute
    return_value = self.execute_callable()
  File "/home/airflow/.local/lib/python3.8/site-packages/airflow/operators/python.py", line 216, in execute_callable
    return self.python_callable(*self.op_args, **self.op_kwargs)
  File "/opt/airflow/dags/pipeline_data_quality.py", line 24, in pipeline
    table1, table2 = generate_tables(df_cleaned)
  File "/opt/airflow/src/data_processing.py", line 17, in generate_tables
    table2 = df_filtered.nlargest(3, 'amount')[['receiving_address', 'amount', 'timestamp']]
  File "/home/airflow/.local/lib/python3.8/site-packages/pandas/core/frame.py", line 7203, in nlargest
    return selectn.SelectNFrame(self, n=n, keep=keep, columns=columns).nlargest()
  File "/home/airflow/.local/lib/python3.8/site-packages/pandas/core/methods/selectn.py", line 54, in nlargest
    return self.compute("nlargest")
  File "/home/airflow/.local/lib/python3.8/site-packages/pandas/core/methods/selectn.py", line 194, in compute
    raise TypeError(
TypeError: Column 'amount' has dtype object, cannot use method 'nlargest' with this dtype
[2024-12-02T06:46:15.109+0000] {taskinstance.py:1138} INFO - Marking task as FAILED. dag_id=data_pipeline, task_id=run_pipeline, execution_date=20241202T064439, start_date=20241202T064442, end_date=20241202T064615
[2024-12-02T06:46:15.168+0000] {standard_task_runner.py:107} ERROR - Failed to execute job 14 for task run_pipeline (Column 'amount' has dtype object, cannot use method 'nlargest' with this dtype; 77)
[2024-12-02T06:46:15.221+0000] {local_task_job_runner.py:234} INFO - Task exited with return code 1
[2024-12-02T06:46:15.304+0000] {taskinstance.py:3281} INFO - 0 downstream tasks scheduled from follow-on schedule check
